Workbook

Sheet Commodities
A1: COICOP Codes
A2: CP01 | B2: Food and non-alcoholic beverages
A3: CP02 | B3: Alcoholic beverages, tobacco and narcotics
A4: CP03 | B4: Clothing and footwear
A5: CP04 | B5: Housing, water, electricity, gas and other fuels
A6: CP05 | B6: Furnishings, household equipment and routine household maintenance
A7: CP06 | B7: Health
A8: CP07 | B8: Transport
A9: CP08 | B9: Communications
A10: CP09 | B10: Recreation and culture
A11: CP10 | B11: Education
A12: CP11 | B12: Restaurants and hotels
A13: CP12 | B13: Miscellaneous goods and services
A14: REFERENCE | B14: COICOP | D14: COMMODITIES (SAM)
A15: =_xlfn.TEXTJOIN(".",TRUE,D15,C15) -> C-AAGR.CP01 | B15: =INDEX($B$2:$B$13,MATCH(C15,$A$2:$A$13,0)) -> Food and non-alcoholic beverages | C15: CP01 | D15: C-AAGR | E15: =_xlfn.TEXTJOIN(", ", TRUE, INDIRECT("Sheet2!" & CHAR(64 + ROW(E15) - 14) & "2:" & CHAR(64 + ROW(E15) - 14) & "50")) -> Paddy rice , Wheat , Cereal grains nec , Vegetables, fruit, nuts , Oil seeds , Sugar cane, sugar beet , Plant-based fibers , Crops nec , Cattle , Pigs , Poultry , Meat animals nec , Animal products nec , Raw milk , Wool, silk-worm cocoons , Manure (conventional treatment) , Manure (biogas treatment) , Products of forestry, logging and related services , Fish and other fishing products; services incidental of fishing
A16: =_xlfn.TEXTJOIN(".",TRUE,D16,C16) -> C-IMIN.CP04 | B16: =INDEX($B$2:$B$13,MATCH(C16,$A$2:$A$13,0)) -> Housing, water, electricity, gas and other fuels | C16: CP04 | D16: C-IMIN | E16: =_xlfn.TEXTJOIN(", ", TRUE, INDIRECT("Sheet2!" & CHAR(64 + ROW(E16) - 14) & "2:" & CHAR(64 + ROW(E16) - 14) & "50")) -> Uranium and thorium ores , Iron ores , Copper ores and concentrates , Nickel ores and concentrates , Aluminium ores and concentrates , Precious metal ores and concentrates , Lead, zinc and tin ores and concentrates , Other non-ferrous metal ores and concentrates , Stone , Sand and clay , Chemical and fertilizer minerals, salt and other mining and quarrying products n.e.c.
A17: =_xlfn.TEXTJOIN(".",TRUE,D17,C17) -> C-IRES.CP01 | B17: =INDEX($B$2:$B$13,MATCH(C17,$A$2:$A$13,0)) -> Food and non-alcoholic beverages | C17: CP01 | D17: C-IRES | E17: =_xlfn.TEXTJOIN(", ", TRUE, INDIRECT("Sheet2!" & CHAR(64 + ROW(E17) - 14) & "2:" & CHAR(64 + ROW(E17) - 14) & "50")) -> Products of meat cattle , Products of meat pigs , Products of meat poultry , Meat products nec , products of Vegetable oils and fats , Dairy products , Processed rice , Sugar , Food products nec , Beverages , Fish products , Tobacco products , Textiles , Wearing apparel; furs , Leather and leather products , Wood and products of wood and cork (except furniture); articles of straw and plaiting materials , Wood material for treatment, Re-processing of secondary wood material into new wood material , Pulp , Secondary paper for treatment, Re-processing of secondary paper into new pulp , Paper and paper products , Printed matter and recorded media , Nuclear fuel , Plastics, basic , Secondary plastic for treatment, Re-processing of secondary plastic into new plastic , N-fertiliser , P- and other fertiliser , Chemicals nec , Additives-Blending Components , Rubber and plastic products , Glass and glass products , Secondary glass for treatment, Re-processing of secondary glass into new glass , Ceramic goods , Bricks, tiles and construction products, in baked clay , Cement, lime and plaster , Ash for treatment, Re-processing of ash into clinker , Other non-metallic mineral products , Fabricated metal products, except machinery and equipment , Machinery and equipment n.e.c. , Office machinery and computers , Electrical machinery and apparatus n.e.c. , Radio, television and communication equipment and apparatus , Medical, precision and optical instruments, watches and clocks , Motor vehicles, trailers and semi-trailers , Other transport equipment , Furniture; other manufactured goods n.e.c. , Secondary raw materials , Bottles for treatment, Recycling of bottles by direct reuse
A18: =_xlfn.TEXTJOIN(".",TRUE,D18,C18) -> C-NG.CP04 | B18: =INDEX($B$2:$B$13,MATCH(C18,$A$2:$A$13,0)) -> Housing, water, electricity, gas and other fuels | C18: CP04 | D18: C-NG | E18: =_xlfn.TEXTJOIN(", ", TRUE, INDIRECT("Sheet2!" & CHAR(64 + ROW(E18) - 14) & "2:" & CHAR(64 + ROW(E18) - 14) & "50")) -> Refinery Gas , Liquefied Petroleum Gases (LPG) , Coke oven gas , Blast Furnace Gas , Oxygen Steel Furnace Gas , Gas Works Gas , Biogas , Distribution services of gaseous fuels through mains
A19: =_xlfn.TEXTJOIN(".",TRUE,D19,C19) -> C-BIO.CP04 | B19: =INDEX($B$2:$B$13,MATCH(C19,$A$2:$A$13,0)) -> Housing, water, electricity, gas and other fuels | C19: CP04 | D19: C-BIO | E19: =_xlfn.TEXTJOIN(", ", TRUE, INDIRECT("Sheet2!" & CHAR(64 + ROW(E19) - 14) & "2:" & CHAR(64 + ROW(E19) - 14) & "50")) -> Charcoal , Biogasoline , Biodiesels , Other Liquid Biofuels , Food waste for treatment: biogasification and land application , Paper waste for treatment: biogasification and land application , Sewage sludge for treatment: biogasification and land application
A20: =_xlfn.TEXTJOIN(".",TRUE,D20,C20) -> C-POWF.CP04 | B20: =INDEX($B$2:$B$13,MATCH(C20,$A$2:$A$13,0)) -> Housing, water, electricity, gas and other fuels | C20: CP04 | D20: C-POWF | E20: =_xlfn.TEXTJOIN(", ", TRUE, INDIRECT("Sheet2!" & CHAR(64 + ROW(E20) - 14) & "2:" & CHAR(64 + ROW(E20) - 14) & "50")) -> Electricity by coal , Electricity by gas , Electricity by nuclear , Electricity by petroleum and other oil derivatives , Electricity nec
A21: =_xlfn.TEXTJOIN(".",TRUE,D21,C21) -> C-POWR.CP04 | B21: =INDEX($B$2:$B$13,MATCH(C21,$A$2:$A$13,0)) -> Housing, water, electricity, gas and other fuels | C21: CP04 | D21: C-POWR | E21: =_xlfn.TEXTJOIN(", ", TRUE, INDIRECT("Sheet2!" & CHAR(64 + ROW(E21) - 14) & "2:" & CHAR(64 + ROW(E21) - 14) & "50")) -> Electricity by hydro , Electricity by wind , Electricity by biomass and waste , Electricity by solar photovoltaic , Electricity by solar thermal , Electricity by tide, wave, ocean , Electricity by Geothermal
A22: =_xlfn.TEXTJOIN(".",TRUE,D22,C22) -> C-POWT.CP04 | B22: =INDEX($B$2:$B$13,MATCH(C22,$A$2:$A$13,0)) -> Housing, water, electricity, gas and other fuels | C22: CP04 | D22: C-POWT | E22: =_xlfn.TEXTJOIN(", ", TRUE, INDIRECT("Sheet2!" & CHAR(64 + ROW(E22) - 14) & "2:" & CHAR(64 + ROW(E22) - 14) & "50")) -> Transmission services of electricity , Distribution and trade services of electricity
A23: =_xlfn.TEXTJOIN(".",TRUE,D23,C23) -> C-LTH.CP04 | B23: =INDEX($B$2:$B$13,MATCH(C23,$A$2:$A$13,0)) -> Housing, water, electricity, gas and other fuels | C23: CP04 | D23: C-LTH | E23: =_xlfn.TEXTJOIN(", ", TRUE, INDIRECT("Sheet2!" & CHAR(64 + ROW(E23) - 14) & "2:" & CHAR(64 + ROW(E23) - 14) & "50")) -> Steam and hot water supply services
A24: =_xlfn.TEXTJOIN(".",TRUE,D24,C24) -> C-COTH.CP05 | B24: =INDEX($B$2:$B$13,MATCH(C24,$A$2:$A$13,0)) -> Furnishings, household equipment and routine household maintenance | C24: CP05 | D24: C-COTH | E24: =_xlfn.TEXTJOIN(", ", TRUE, INDIRECT("Sheet2!" & CHAR(64 + ROW(E24) - 14) & "2:" & CHAR(64 + ROW(E24) - 14) & "50")) -> Collected and purified water, distribution services of water , Post and telecommunication services , Membership organisation services n.e.c. , Recreational, cultural and sporting services , Other services , Private households with employed persons
A25: =_xlfn.TEXTJOIN(".",TRUE,D25,C25) -> C-CCON.CP04 | B25: =INDEX($B$2:$B$13,MATCH(C25,$A$2:$A$13,0)) -> Housing, water, electricity, gas and other fuels | C25: CP04 | D25: C-CCON | E25: =_xlfn.TEXTJOIN(", ", TRUE, INDIRECT("Sheet2!" & CHAR(64 + ROW(E25) - 14) & "2:" & CHAR(64 + ROW(E25) - 14) & "50")) -> Construction work , Secondary construction material for treatment, Re-processing of secondary construction material into aggregates
A26: =_xlfn.TEXTJOIN(".",TRUE,D26,C26) -> C-CWSR.CP07 | B26: =INDEX($B$2:$B$13,MATCH(C26,$A$2:$A$13,0)) -> Transport | C26: CP07 | D26: C-CWSR | E26: =_xlfn.TEXTJOIN(", ", TRUE, INDIRECT("Sheet2!" & CHAR(64 + ROW(E26) - 14) & "2:" & CHAR(64 + ROW(E26) - 14) & "50")) -> Sale, maintenance, repair of motor vehicles, motor vehicles parts, motorcycles, motor cycles parts and accessoiries , Retail trade services of motor fuel , Wholesale trade and commission trade services, except of motor vehicles and motorcycles , Retail trade services, except of motor vehicles and motorcycles; repair services of personal and household goods
... A40: =_xlfn.TEXTJOIN(".",TRUE,D40,C40) -> C-OIL-HDI.CP04 | B40: =INDEX($B$2:$B$13,MATCH(C40,$A$2:$A$13,0)) -> Housing, water, electricity, gas and other fuels | C40: CP04 | D40: C-OIL-HDI | E40: =_xlfn.TEXTJOIN(", ", TRUE, INDIRECT("Sheet2!" & CHAR(64 + ROW(E40) - 14) & "2:" & CHAR(64 + ROW(E40) - 14) & "50")) -> Heavy Fuel Oil , Lubricants , Bitumen , Paraffin Waxes
A41: =_xlfn.TEXTJOIN(".",TRUE,D41,C41) -> C-OIL-LDSF.CP04 | B41: =INDEX($B$2:$B$13,MATCH(C41,$A$2:$A$13,0)) -> Housing, water, electricity, gas and other fuels | C41: CP04 | D41: C-OIL-LDSF | E41: =_xlfn.TEXTJOIN(", ", TRUE,Sheet2!AA2:AA3) -> Naphtha , White Spirit & SBP
A42: =_xlfn.TEXTJOIN(".",TRUE,D42,C42) -> C-IMEA.CP04 | B42: =INDEX($B$2:$B$13,MATCH(C42,$A$2:$A$13,0)) -> Housing, water, electricity, gas and other fuels | C42: CP04 | D42: C-IMEA | E42: =_xlfn.TEXTJOIN(", ", TRUE,Sheet2!AB2:AB20) -> Basic iron and steel and of ferro-alloys and first products thereof , Secondary steel for treatment, Re-processing of secondary steel into new steel , Precious metals , Secondary preciuos metals for treatment, Re-processing of secondary preciuos metals into new preciuos metals , Aluminium and aluminium products , Secondary aluminium for treatment, Re-processing of secondary aluminium into new aluminium , Lead, zinc and tin and products thereof , Secondary lead for treatment, Re-processing of secondary lead into new lead , Copper products , Secondary copper for treatment, Re-processing of secondary copper into new copper , Other non-ferrous metal products , Secondary other non-ferrous metals for treatment, Re-processing of secondary other non-ferrous metals into new other non-ferrous metals , Foundry work services
A43: =_xlfn.TEXTJOIN(".",TRUE,D43,C43) -> C-C_TWAS.CP07 | B43: =INDEX($B$2:$B$13,MATCH(C43,$A$2:$A$13,0)) -> Transport | C43: CP07 | D43: C-C_TWAS | E43: =_xlfn.TEXTJOIN(", ", TRUE,Sheet2!AC2:AC20) -> Sea and coastal water transportation services
A44: =_xlfn.TEXTJOIN(".",TRUE,D44,C44) -> C-C_TWAI.CP07 | B44: =INDEX($B$2:$B$13,MATCH(C44,$A$2:$A$13,0)) -> Transport | C44: CP07 | D44: C-C_TWAI | E44: =_xlfn.TEXTJOIN(", ", TRUE,Sheet2!AD2:AD20) -> Inland water transportation services
A45: =_xlfn.TEXTJOIN(".",TRUE,D45,C45) -> C-C_TAIR.CP07 | B45: =INDEX($B$2:$B$13,MATCH(C45,$A$2:$A$13,0)) -> Transport | C45: CP07 | D45: C-C_TAIR | E45: =_xlfn.TEXTJOIN(", ", TRUE,Sheet2!AE2:AE20) -> Air transport services
A46: =_xlfn.TEXTJOIN(".",TRUE,D46,C46) -> C-COIL.CP04 | B46: =INDEX($B$2:$B$13,MATCH(C46,$A$2:$A$13,0)) -> Housing, water, electricity, gas and other fuels | C46: CP04 | D46: C-COIL | E46: =_xlfn.TEXTJOIN(", ", TRUE,Sheet2!AF2:AF20) -> Other Hydrocarbons
A48: =_xlfn.TEXTJOIN(", ",TRUE,A15:A46) -> C-AAGR.CP01, C-IMIN.CP04, C-IRES.CP01, C-NG.CP04, C-BIO.CP04, C-POWF.CP04, C-POWR.CP04, C-POWT.CP04, C-LTH.CP04, C-COTH.CP05, C-CCON.CP04, C-CWSR.CP07, C-COFF.CP11, C-C_TRAI.CP07, C-C_TLND.CP07, C-C_TPIP.CP07, C-CHEA.CP06, C-Waste.CP04, C-COAL.CP04, C-CRUDE-OIL.CP04, C-GASE.CP04, C-OIL-GSL.CP04, C-OIL-JET.CP04, C-OIL-KER.CP04, C-OIL-DSL.CP04, C-OIL-HDI.CP04, C-OIL-LDSF.CP04, C-IMEA.CP04, C-C_TWAS.CP07, C-C_TWAI.CP07, C-C_TAIR.CP07, C-COIL.CP04
A50: LATEX - code
A51: CP01 | B51: C-AAGR | D51: =_xlfn.TEXTJOIN(" & ",TRUE,B51,A51) -> C-AAGR & CP01
A52: CP01 | B52: C-IRES | D52: =_xlfn.TEXTJOIN(" & ",TRUE,B52,A52) -> C-IRES & CP01
A53: CP04 | B53: C-IMIN | D53: =_xlfn.TEXTJOIN(" & ",TRUE,B53,A53) -> C-IMIN & CP04
A54: CP04 | B54: C-NG | D54: =_xlfn.TEXTJOIN(" & ",TRUE,B54,A54) -> C-NG & CP04
A55: CP04 | B55: C-BIO | D55: =_xlfn.TEXTJOIN(" & ",TRUE,B55,A55) -> C-BIO & CP04
...

Sheet Sectors
A1: REFERENCE | B1: SECTORS | D1: COMMODITIES (SAM)
A2: =_xlfn.TEXTJOIN(".",TRUE,D2,C2) -> AAGR.C | B2: =INDEX($B$29:$B$46,MATCH(C2,$A$29:$A$46,0)) -> Manufacturing | C2: C | D2: AAGR | E2: =_xlfn.TEXTJOIN(", ", TRUE, INDIRECT("Sheet4!" & CHAR(64 + ROW(F15) - 14) & "2:" & CHAR(64 + ROW(F15) - 14) & "50")) -> Cultivation of paddy rice , Cultivation of wheat , Cultivation of cereal grains nec , Cultivation of vegetables, fruit, nuts , Cultivation of oil seeds , Cultivation of sugar cane, sugar beet , Cultivation of plant-based fibers , Cultivation of crops nec , Cattle farming , Pigs farming , Poultry farming , Meat animals nec , Animal products nec , Raw milk , Wool, silk-worm cocoons , Manure treatment (conventional), storage and land application , Manure treatment (biogas), storage and land application , Forestry, logging and related service activities , Fishing, operating of fish hatcheries and fish farms; service activities incidental to fishing
A3: =_xlfn.TEXTJOIN(".",TRUE,D3,C3) -> COAL.B | B3: =INDEX($B$29:$B$46,MATCH(C3,$A$29:$A$46,0)) -> Mining and quarrying | C3: B | D3: COAL | E3: =_xlfn.TEXTJOIN(", ", TRUE, INDIRECT("Sheet4!" & CHAR(64 + ROW(F16) - 14) & "2:" & CHAR(64 + ROW(F16) - 14) & "50")) -> Mining of coal and lignite; extraction of peat
A4: =_xlfn.TEXTJOIN(".",TRUE,D4,C4) -> COIL.B | B4: =INDEX($B$29:$B$46,MATCH(C4,$A$29:$A$46,0)) -> Mining and quarrying | C4: B | D4: COIL | E4: =_xlfn.TEXTJOIN(", ", TRUE, INDIRECT("Sheet4!" & CHAR(64 + ROW(F17) - 14) & "2:" & CHAR(64 + ROW(F17) - 14) & "50")) -> Extraction of crude petroleum and services related to crude oil extraction, excluding surveying , Extraction of natural gas and services related to natural gas extraction, excluding surveying , Extraction, liquefaction, and regasification of other petroleum and gaseous materials , Petroleum Refinery
A5: =_xlfn.TEXTJOIN(".",TRUE,D5,C5) -> IMIN.B | B5: =INDEX($B$29:$B$46,MATCH(C5,$A$29:$A$46,0)) -> Mining and quarrying | C5: B | D5: IMIN | E5: =_xlfn.TEXTJOIN(", ", TRUE, INDIRECT("Sheet4!" & CHAR(64 + ROW(F18) - 14) & "2:" & CHAR(64 + ROW(F18) - 14) & "50")) -> Mining of uranium and thorium ores , Mining of iron ores , Mining of copper ores and concentrates , Mining of nickel ores and concentrates , Mining of aluminium ores and concentrates , Mining of precious metal ores and concentrates , Mining of lead, zinc and tin ores and concentrates , Mining of other non-ferrous metal ores and concentrates , Quarrying of stone , Quarrying of sand and clay , Mining of chemical and fertilizer minerals, production of salt, other mining and quarrying n.e.c. , Manufacture of coke oven products , Manufacture of basic iron and steel and of ferro-alloys and first products thereof , Re-processing of secondary steel into new steel , Precious metals production , Re-processing of secondary preciuos metals into new preciuos metals , Lead, zinc and tin production , Re-processing of secondary lead into new lead , Copper production , Re-processing of secondary copper into new copper , Other non-ferrous metal production , Re-processing of secondary other non-ferrous metals into new other non-ferrous metals , Casting of metals
A6: =_xlfn.TEXTJOIN(".",TRUE,D6,C6) -> IRES.C | B6: =INDEX($B$29:$B$46,MATCH(C6,$A$29:$A$46,0)) -> Manufacturing | C6: C | D6: IRES | E6: =_xlfn.TEXTJOIN(", ", TRUE, INDIRECT("Sheet4!" & CHAR(64 + ROW(F19) - 14) & "2:" & CHAR(64 + ROW(F19) - 14) & "50")) -> Processing of meat cattle , Processing of meat pigs , Processing of meat poultry , Production of meat products nec , Processing vegetable oils and fats , Processing of dairy products , Processed rice , Sugar refining , Processing of Food products nec , Manufacture of beverages , Manufacture of fish products , Manufacture of tobacco products , Manufacture of textiles , Manufacture of wearing apparel; dressing and dyeing of fur , Tanning and dressing of leather; manufacture of luggage, handbags, saddlery, harness and footwear , Manufacture of wood and of products of wood and cork, except furniture; manufacture of articles of straw and plaiting materials , Re-processing of secondary wood material into new wood material , Pulp , Re-processing of secondary paper into new pulp , Paper , Publishing, printing and reproduction of recorded media , Processing of nuclear fuel , Plastics, basic , Re-processing of secondary plastic into new plastic , N-fertiliser , P- and other fertiliser , Chemicals nec , Manufacture of rubber and plastic products , Manufacture of glass and glass products , Re-processing of secondary glass into new glass , Manufacture of ceramic goods , Manufacture of bricks, tiles and construction products, in baked clay , Manufacture of cement, lime and plaster , Re-processing of ash into clinker , Manufacture of other non-metallic mineral products n.e.c. , Manufacture of fabricated metal products, except machinery and equipment , Manufacture of machinery and equipment n.e.c. , Manufacture of office machinery and computers , Manufacture of electrical machinery and apparatus n.e.c. , Manufacture of radio, television and communication equipment and apparatus , Manufacture of medical, precision and optical instruments, watches and clocks , Manufacture of motor vehicles, trailers and semi-trailers , Manufacture of other transport equipment , Manufacture of furniture; manufacturing n.e.c. , Recycling of waste and scrap , Recycling of bottles by direct reuse
A7: =_xlfn.TEXTJOIN(".",TRUE,D7,C7) -> IALA.B | B7: =INDEX($B$29:$B$46,MATCH(C7,$A$29:$A$46,0)) -> Mining and quarrying | C7: B | D7: IALA | E7: =_xlfn.TEXTJOIN(", ", TRUE, INDIRECT("Sheet4!" & CHAR(64 + ROW(F20) - 14) & "2:" & CHAR(64 + ROW(F20) - 14) & "50")) -> Aluminium production , Re-processing of secondary aluminium into new aluminium
A8: =_xlfn.TEXTJOIN(".",TRUE,D8,C8) -> POWF.D | B8: =INDEX($B$29:$B$46,MATCH(C8,$A$29:$A$46,0)) -> Electricity, gas, steam and air conditioning supply | C8: D | D8: POWF | E8: =_xlfn.TEXTJOIN(", ", TRUE, INDIRECT("Sheet4!" & CHAR(64 + ROW(F21) - 14) & "2:" & CHAR(64 + ROW(F21) - 14) & "50")) -> Production of electricity by coal , Production of electricity by gas , Production of electricity by nuclear , Production of electricity by petroleum and other oil derivatives , Production of electricity nec
A9: =_xlfn.TEXTJOIN(".",TRUE,D9,C9) -> POWR.D | B9: =INDEX($B$29:$B$46,MATCH(C9,$A$29:$A$46,0)) -> Electricity, gas, steam and air conditioning supply | C9: D | D9: POWR | E9: =_xlfn.TEXTJOIN(", ", TRUE, INDIRECT("Sheet4!" & CHAR(64 + ROW(F22) - 14) & "2:" & CHAR(64 + ROW(F22) - 14) & "50")) -> Production of electricity by hydro , Production of electricity by wind , Production of electricity by biomass and waste , Production of electricity by solar photovoltaic , Production of electricity by solar thermal , Production of electricity by tide, wave, ocean , Production of electricity by Geothermal
A10: =_xlfn.TEXTJOIN(".",TRUE,D10,C10) -> POWT.D | B10: =INDEX($B$29:$B$46,MATCH(C10,$A$29:$A$46,0)) -> Electricity, gas, steam and air conditioning supply | C10: D | D10: POWT | E10: =_xlfn.TEXTJOIN(", ", TRUE, INDIRECT("Sheet4!" & CHAR(64 + ROW(F23) - 14) & "2:" & CHAR(64 + ROW(F23) - 14) & "50")) -> Transmission of electricity , Distribution and trade of electricity
A11: =_xlfn.TEXTJOIN(".",TRUE,D11,C11) -> NG.D | B11: =INDEX($B$29:$B$46,MATCH(C11,$A$29:$A$46,0)) -> Electricity, gas, steam and air conditioning supply | C11: D | D11: NG | E11: =_xlfn.TEXTJOIN(", ", TRUE, INDIRECT("Sheet4!" & CHAR(64 + ROW(F24) - 14) & "2:" & CHAR(64 + ROW(F24) - 14) & "50")) -> Manufacture of gas; distribution of gaseous fuels through mains
A12: =_xlfn.TEXTJOIN(".",TRUE,D12,C12) -> LTH.D | B12: =INDEX($B$29:$B$46,MATCH(C12,$A$29:$A$46,0)) -> Electricity, gas, steam and air conditioning supply | C12: D | D12: LTH | E12: =_xlfn.TEXTJOIN(", ", TRUE, INDIRECT("Sheet4!" & CHAR(64 + ROW(F25) - 14) & "2:" & CHAR(64 + ROW(F25) - 14) & "50")) -> Steam and hot water supply
A13: =_xlfn.TEXTJOIN(".",TRUE,D13,C13) -> COTH.E | B13: =INDEX($B$29:$B$46,MATCH(C13,$A$29:$A$46,0)) -> Water supply; sewerage, waste management and remediation activities | C13: E | D13: COTH | E13: =_xlfn.TEXTJOIN(", ", TRUE, INDIRECT("Sheet4!" & CHAR(64 + ROW(F26) - 14) & "2:" & CHAR(64 + ROW(F26) - 14) & "50")) -> Collection, purification and distribution of water , Post and telecommunications , Activities of membership organisation n.e.c. , Recreational, cultural and sporting activities , Other service activities , Private households with employed persons
... A25: =_xlfn.TEXTJOIN(".",TRUE,D25,C25) -> BIO.E | B25: =INDEX($B$29:$B$46,MATCH(C25,$A$29:$A$46,0)) -> Water supply; sewerage, waste management and remediation activities | C25: E | D25: BIO | E25: =_xlfn.TEXTJOIN(", ", TRUE, INDIRECT("Sheet4!" & CHAR(64 + ROW(F38) - 14) & "2:" & CHAR(64 + ROW(F38) - 14) & "50")) -> Biogasification of food waste, incl. land application , Biogasification of paper, incl. land application , Biogasification of sewage slugde, incl. land application
A27: =_xlfn.TEXTJOIN(", ",TRUE,A2:A25) -> AAGR.C, COAL.B, COIL.B, IMIN.B, IRES.C, IALA.B, POWF.D, POWR.D, POWT.D, NG.D, LTH.D, COTH.E, CCON.F, CWSR.G, COFF.L, C_TRAI.H, C_TLND.H, C_TPIP.H, C_TWAS.H, C_TWAI.H, C_TAIR.H, CHEA.Q, Waste.E, BIO.E
A28: NACE CODES
A29: B | B29: Mining and quarrying
A30: C | B30: Manufacturing
A31: D | B31: Electricity, gas, steam and air conditioning supply
A32: E | B32: Water supply; sewerage, waste management and remediation activities
A33: F | B33: Construction
A34: G | B34: Wholesale and retail trade; repair of motor vehicles and motorcycles
A35: H | B35: Transportation and storage
A36: I | B36: Accommodation and food service activities
A37: J | B37: Information and communication
A38: K | B38: Financial and insurance activities
A39: L | B39: Real estate activities
A40: M | B40: Professional, scientific and technical activities
... A46: S | B46: Other service activities
A48: LATEX - code
A49: B | B49: COAL | D49: =_xlfn.TEXTJOIN(" & ",TRUE,B49,A49) -> COAL & B
A50: B | B50: COIL | D50: =_xlfn.TEXTJOIN(" & ",TRUE,B50,A50) -> COIL & B
A51: B | B51: IALA | D51: =_xlfn.TEXTJOIN(" & ",TRUE,B51,A51) -> IALA & B
A52: B | B52: IMIN | D52: =_xlfn.TEXTJOIN(" & ",TRUE,B52,A52) -> IMIN & B
A53: C | B53: AAGR | D53: =_xlfn.TEXTJOIN(" & ",TRUE,B53,A53) -> AAGR & C
A54: C | B54: IRES | D54: =_xlfn.TEXTJOIN(" & ",TRUE,B54,A54) -> IRES & C
A55: D | B55: LTH | D55: =_xlfn.TEXTJOIN(" & ",TRUE,B55,A55) -> LTH & D
A56: D | B56: NG | D56: =_xlfn.TEXTJOIN(" & ",TRUE,B56,A56) -> NG & D
A57: D | B57: POWF | D57: =_xlfn.TEXTJOIN(" & ",TRUE,B57,A57) -> POWF & D
A58: D | B58: POWR | D58: =_xlfn.TEXTJOIN(" & ",TRUE,B58,A58) -> POWR & D
...

Sheet Sheet4
A1: AAGR | B1: COAL | C1: COIL | D1: IMIN | E1: IRES | F1: IALA | G1: POWF | H1: POWR | I1: POWT | J1: NG | K1: LTH | L1: COTH | M1: CCON | N1: CWSR | O1: COFF | P1: C_TRAI | Q1: C_TLND | R1: C_TPIP | S1: C_TWAS | T1: C_TWAI | U1: C_TAIR | V1: CHEA | W1: Waste | X1: BIO
A2: Cultivation of paddy rice | B2: Mining of coal and lignite; extraction of peat | C2: Extraction of crude petroleum and services related to crude oil extraction, excluding surveying | D2: Mining of uranium and thorium ores | E2: Processing of meat cattle | F2: Aluminium production | G2: Production of electricity by coal | H2: Production of electricity by hydro | I2: Transmission of electricity | J2: Manufacture of gas; distribution of gaseous fuels through mains | K2: Steam and hot water supply | L2: Collection, purification and distribution of water | M2: Construction | N2: Collection, purification and distribution of water | O2: Hotels and restaurants | P2: Transport via railways | Q2: Other land transport | R2: Transport via pipelines | S2: Sea and coastal water transport | T2: Inland water transport | U2: Air transport | V2: Education | W2: Incineration of waste: Food | X2: Biogasification of food waste, incl. land application
A3: Cultivation of wheat | C3: Extraction of natural gas and services related to natural gas extraction, excluding surveying | D3: Mining of iron ores | E3: Processing of meat pigs | F3: Re-processing of secondary aluminium into new aluminium | G3: Production of electricity by gas | H3: Production of electricity by wind | I3: Distribution and trade of electricity | L3: Post and telecommunications | M3: Re-processing of secondary construction material into aggregates | N3: Post and telecommunications | O3: Supporting and auxiliary transport activities; activities of travel agencies | V3: Health and social work | W3: Incineration of waste: Paper | X3: Biogasification of paper, incl. land application
A4: Cultivation of cereal grains nec | C4: Extraction, liquefaction, and regasification of other petroleum and gaseous materials | D4: Mining of copper ores and concentrates | E4: Processing of meat poultry | G4: Production of electricity by nuclear | H4: Production of electricity by biomass and waste | L4: Activities of membership organisation n.e.c. | N4: Activities of membership organisation n.e.c. | O4: Financial intermediation, except insurance and pension funding | W4: Incineration of waste: Plastic | X4: Biogasification of sewage slugde, incl. land application
A5: Cultivation of vegetables, fruit, nuts | C5: Petroleum Refinery | D5: Mining of nickel ores and concentrates | E5: Production of meat products nec | G5: Production of electricity by petroleum and other oil derivatives | H5: Production of electricity by solar photovoltaic | L5: Recreational, cultural and sporting activities | N5: Recreational, cultural and sporting activities | O5: Insurance and pension funding, except compulsory social security | W5: Incineration of waste: Metals and Inert materials
A6: Cultivation of oil seeds | D6: Mining of aluminium ores and concentrates | E6: Processing vegetable oils and fats | G6: Production of electricity nec | H6: Production of electricity by solar thermal | L6: Other service activities | N6: Other service activities | O6: Activities auxiliary to financial intermediation | W6: Incineration of waste: Textiles
A7: Cultivation of sugar cane, sugar beet | D7: Mining of precious metal ores and concentrates | E7: Processing of dairy products | H7: Production of electricity by tide, wave, ocean | L7: Private households with employed persons | N7: Private households with employed persons | O7: Real estate activities | W7: Incineration of waste: Wood
A8: Cultivation of plant-based fibers | D8: Mining of lead, zinc and tin ores and concentrates | E8: Processed rice | H8: Production of electricity by Geothermal | O8: Renting of machinery and equipment without operator and of personal and household goods | W8: Incineration of waste: Oil-Hazardous waste
A9: Cultivation of crops nec | D9: Mining of other non-ferrous metal ores and concentrates | E9: Sugar refining | O9: Computer and related activities | W9: Composting of food waste, incl. land application
A10: Cattle farming | D10: Quarrying of stone | E10: Processing of Food products nec | O10: Research and development | W10: Composting of paper and wood, incl. land application
A11: Pigs farming | D11: Quarrying of sand and clay | E11: Manufacture of beverages | O11: Other business activities | W11: Waste water treatment, food
A12: Poultry farming | D12: Mining of chemical and fertilizer minerals, production of salt, other mining and quarrying n.e.c. | E12: Manufacture of fish products | O12: Public administration and defence; compulsory social security | W12: Waste water treatment, other
A13: Meat animals nec | D13: Manufacture of coke oven products | E13: Manufacture of tobacco products | O13: Extra-territorial organizations and bodies | W13: Landfill of waste: Food
A14: Animal products nec | D14: Manufacture of basic iron and steel and of ferro-alloys and first products thereof | E14: Manufacture of textiles | W14: Landfill of waste: Paper
A15: Raw milk | D15: Re-processing of secondary steel into new steel | E15: Manufacture of wearing apparel; dressing and dyeing of fur | W15: Landfill of waste: Plastic
A16: Wool, silk-worm cocoons | D16: Precious metals production | E16: Tanning and dressing of leather; manufacture of luggage, handbags, saddlery, harness and footwear | W16: Landfill of waste: Inert-metal-hazardous
A17: Manure treatment (conventional), storage and land application | D17: Re-processing of secondary preciuos metals into new preciuos metals | E17: Manufacture of wood and of products of wood and cork, except furniture; manufacture of articles of straw and plaiting materials | W17: Landfill of waste: Textiles
A18: Manure treatment (biogas), storage and land application | D18: Lead, zinc and tin production | E18: Re-processing of secondary wood material into new wood material | W18: Landfill of waste: Wood
A19: Forestry, logging and related service activities | D19: Re-processing of secondary lead into new lead | E19: Pulp
A20: Fishing, operating of fish hatcheries and fish farms; service activities incidental to fishing | D20: Copper production | E20: Re-processing of secondary paper into new pulp
D21: Re-processing of secondary copper into new copper | E21: Paper
D22: Other non-ferrous metal production | E22: Publishing, printing and reproduction of recorded media
D23: Re-processing of secondary other non-ferrous metals into new other non-ferrous metals | E23: Processing of nuclear fuel
D24: Casting of metals | E24: Plastics, basic
E25: Re-processing of secondary plastic into new plastic
E26: N-fertiliser
E27: P- and other fertiliser
E28: Chemicals nec
E29: Manufacture of rubber and plastic products
E30: Manufacture of glass and glass products
E31: Re-processing of secondary glass into new glass
E32: Manufacture of ceramic goods
E33: Manufacture of bricks, tiles and construction products, in baked clay
E34: Manufacture of cement, lime and plaster
E35: Re-processing of ash into clinker
E36: Manufacture of other non-metallic mineral products n.e.c.
... E47: Recycling of bottles by direct reuse

Sheet Sheet2
A1: C-AAGR | B1: C-IMIN | C1: C-IRES | D1: C-NG | E1: C-BIO | F1: C-POWF | G1: C-POWR | H1: C-POWT | I1: C-LTH | J1: C-COTH | K1: C-CCON | L1: C-CWSR | M1: C-COFF | N1: C-C_TRAI | O1: C-C_TLND | P1: C-C_TPIP | Q1: C-CHEA | R1: C-Waste | S1: C-COAL | T1: C-CRUDE-OIL | U1: C-GASE | V1: C-OIL-GSL | W1: C-OIL-JET | X1: C-OIL-KER | Y1: C-OIL-DSL | Z1: C-OIL-HDI | AA1: C-OIL-LDSF | AB1: C-IMEA | AC1: C-C_TWAS | AD1: C-C_TWAI | AE1: C-C_TAIR | AF1: C-COIL
A2: Paddy rice | B2: Uranium and thorium ores | C2: Products of meat cattle | D2: Refinery Gas | E2: Charcoal | F2: Electricity by coal | G2: Electricity by hydro | H2: Transmission services of electricity | I2: Steam and hot water supply services | J2: Collected and purified water, distribution services of water | K2: Construction work | L2: Sale, maintenance, repair of motor vehicles, motor vehicles parts, motorcycles, motor cycles parts and accessoiries | M2: Warehousing and support services for transportation | N2: Railway transportation services | O2: Other land transportation services | P2: Transportation services via pipelines | Q2: Education services | R2: Food waste for treatment: incineration | S2: Anthracite | T2: Crude petroleum and services related to crude oil extraction, excluding surveying | U2: Natural gas and services related to natural gas extraction, excluding surveying | V2: Motor Gasoline | W2: Aviation Gasoline | X2: Kerosene | Y2: Gas-Diesel Oil | Z2: Heavy Fuel Oil | AA2: Naphtha | AB2: Basic iron and steel and of ferro-alloys and first products thereof | AC2: Sea and coastal water transportation services | AD2: Inland water transportation services | AE2: Air transport services | AF2: Other Hydrocarbons
A3: Wheat | B3: Iron ores | C3: Products of meat pigs | D3: Liquefied Petroleum Gases (LPG) | E3: Biogasoline | F3: Electricity by gas | G3: Electricity by wind | H3: Distribution and trade services of electricity | J3: Post and telecommunication services | K3: Secondary construction material for treatment, Re-processing of secondary construction material into aggregates | L3: Retail trade services of motor fuel | M3: Postal and courier services | Q3: Health and social work services | R3: Paper waste for treatment: incineration | S3: Coking Coal | T3: Refinery Feedstocks | U3: Natural Gas Liquids | V3: Ethane | W3: Gasoline Type Jet Fuel | Z3: Lubricants | AA3: White Spirit & SBP | AB3: Secondary steel for treatment, Re-processing of secondary steel into new steel
A4: Cereal grains nec | B4: Copper ores and concentrates | C4: Products of meat poultry | D4: Coke oven gas | E4: Biodiesels | F4: Electricity by nuclear | G4: Electricity by biomass and waste | J4: Membership organisation services n.e.c. | L4: Wholesale trade and commission trade services, except of motor vehicles and motorcycles | M4: Accommodation and food services | R4: Plastic waste for treatment: incineration | S4: Other Bituminous Coal | V4: Non-specified Petroleum Products | W4: Kerosene Type Jet Fuel | Z4: Bitumen | AB4: Precious metals
A5: Vegetables, fruit, nuts | B5: Nickel ores and concentrates | C5: Meat products nec | D5: Blast Furnace Gas | E5: Other Liquid Biofuels | F5: Electricity by petroleum and other oil derivatives | G5: Electricity by solar photovoltaic | J5: Recreational, cultural and sporting services | L5: Retail trade services, except of motor vehicles and motorcycles; repair services of personal and household goods | R5: Intert-metal waste for treatment: incineration | S5: Sub-Bituminous Coal | Z5: Paraffin Waxes | AB5: Secondary preciuos metals for treatment, Re-processing of secondary preciuos metals into new preciuos metals
A6: Oil seeds | B6: Aluminium ores and concentrates | C6: products of Vegetable oils and fats | D6: Oxygen Steel Furnace Gas | E6: Food waste for treatment: biogasification and land application | F6: Electricity nec | G6: Electricity by solar thermal | J6: Other services | R6: Textiles waste for treatment: incineration | S6: Patent Fuel | AB6: Aluminium and aluminium products
A7: Sugar cane, sugar beet | B7: Precious metal ores and concentrates | C7: Dairy products | D7: Gas Works Gas | E7: Paper waste for treatment: biogasification and land application | G7: Electricity by tide, wave, ocean | J7: Private households with employed persons | R7: Wood waste for treatment: incineration | S7: Lignite-Brown Coal | AB7: Secondary aluminium for treatment, Re-processing of secondary aluminium into new aluminium
A8: Plant-based fibers | B8: Lead, zinc and tin ores and concentrates | C8: Processed rice | D8: Biogas | E8: Sewage sludge for treatment: biogasification and land application | G8: Electricity by Geothermal | R8: Oil-hazardous waste for treatment: incineration | S8: BKB-Peat Briquettes | AB8: Lead, zinc and tin and products thereof
A9: Crops nec | B9: Other non-ferrous metal ores and concentrates | C9: Sugar | D9: Distribution services of gaseous fuels through mains | R9: Food waste for treatment: composting and land application | S9: Peat | AB9: Secondary lead for treatment, Re-processing of secondary lead into new lead
A10: Cattle | B10: Stone | C10: Food products nec | R10: Paper and wood waste for treatment: composting and land application | S10: Coke Oven Coke | AB10: Copper products
A11: Pigs | B11: Sand and clay | C11: Beverages | R11: Food waste for treatment: waste water treatment | S11: Gas Coke | AB11: Secondary copper for treatment, Re-processing of secondary copper into new copper
A12: Poultry | B12: Chemical and fertilizer minerals, salt and other mining and quarrying products n.e.c. | C12: Fish products | R12: Other waste for treatment: waste water treatment | S12: Coal Tar | AB12: Other non-ferrous metal products
A13: Meat animals nec | C13: Tobacco products | R13: Food waste for treatment: landfill | S13: Petroleum Coke | AB13: Secondary other non-ferrous metals for treatment, Re-processing of secondary other non-ferrous metals into new other non-ferrous metals
A14: Animal products nec | C14: Textiles | R14: Paper for treatment: landfill | AB14: Foundry work services
A15: Raw milk | C15: Wearing apparel; furs | R15: Plastic waste for treatment: landfill
A16: Wool, silk-worm cocoons | C16: Leather and leather products | R16: Inert-metal-hazardous waste for treatment: landfill
A17: Manure (conventional treatment) | C17: Wood and products of wood and cork (except furniture); articles of straw and plaiting materials | R17: Textiles waste for treatment: landfill
A18: Manure (biogas treatment) | C18: Wood material for treatment, Re-processing of secondary wood material into new wood material | R18: Wood waste for treatment: landfill
A19: Products of forestry, logging and related services | C19: Pulp
A20: Fish and other fishing products; services incidental of fishing | C20: Secondary paper for treatment, Re-processing of secondary paper into new pulp
C21: Paper and paper products
C22: Printed matter and recorded media
C23: Nuclear fuel
C24: Plastics, basic
C25: Secondary plastic for treatment, Re-processing of secondary plastic into new plastic
C26: N-fertiliser
C27: P- and other fertiliser
C28: Chemicals nec
C29: Additives-Blending Components
C30: Rubber and plastic products
C31: Glass and glass products
C32: Secondary glass for treatment, Re-processing of secondary glass into new glass
... C48: Bottles for treatment, Recycling of bottles by direct reuse

Sheet Sheet5
F1: C-AAGR | H1: =_xlfn.TEXTJOIN(", ",TRUE,F:F) -> C-AAGR, C-IMIN, C-IRES, C-NG, C-BIO, C-POWF, C-POWR, C-POWT, C-LTH, C-COTH, C-CCON, C-CWSR, C-COFF, C-C_TRAI, C-C_TLND, C-C_TPIP, C-CHEA, C-Waste, C-COAL, C-CRUDE-OIL, C-GASE, C-OIL-GSL, C-OIL-JET, C-OIL-KER, C-OIL-DSL, C-OIL-HDI, C-OIL-LDSF, C-IMEA, C-C_TWAS, C-C_TWAI, C-C_TAIR, C-COIL
F2: C-IMIN
F3: C-IRES
F4: C-NG
F5: C-BIO
F6: C-POWF
F7: C-POWR
F8: C-POWT
F9: C-LTH
F10: C-COTH
F11: C-CCON
F12: C-CWSR
F13: C-COFF
... F32: C-COIL
